Workbook

Sheet Summary
A1: Prof. Peptide Affiliate Commission Tracker
A2: Compiled from Gmail commission notifications | Last updated: 2026-05-18
A4: Vendor | B4: Orders / Referrals | C4: Total Sales | D4: Total Commissions | E4: Avg Commission | F4: Notes
A5: Peptide Partners | B5: =COUNTIF(Transactions!B:B,A5) -> 12 | C5: =SUMIF(Transactions!B:B,A5,Transactions!D:D) -> 0 | D5: =SUMIF(Transactions!B:B,A5,Transactions!E:E) -> 426.06 | E5: =IFERROR(D5/B5,0) -> 35.505 | F5: Commission-only data in emails. Sales amounts not in PP notification emails. Mark notes additional historical commissions visible in PP affiliate dashboard.
A6: Ascension Peptides | B6: =COUNTIF(Transactions!B:B,A6) -> 7 | C6: =SUMIF(Transactions!B:B,A6,Transactions!D:D) -> 0 | D6: =SUMIF(Transactions!B:B,A6,Transactions!E:E) -> 205.98 | E6: =IFERROR(D6/B6,0) -> 29.425714 | F6: Commission-only data in emails. Sale amounts not in notification emails.
A7: EZ Peptides | B7: =COUNTIF(Transactions!B:B,A7) -> 5 | C7: =SUMIF(Transactions!B:B,A7,Transactions!D:D) -> 1762.8 | D7: =SUMIF(Transactions!B:B,A7,Transactions!E:E) -> 170.28 | E7: =IFERROR(D7/B7,0) -> 34.056 | F7: Full data: sales + commissions visible in notifications.
A8: Royal Peptides | B8: =COUNTIF(Transactions!B:B,A8) -> 7 | C8: =SUMIF(Transactions!B:B,A8,Transactions!D:D) -> 1547.28 | D8: =SUMIF(Transactions!B:B,A8,Transactions!E:E) -> 82.35 | E8: =IFERROR(D8/B8,0) -> 11.764286 | F8: Some referrals marked as refunded/unpaid (commission reverted to $0 after initial credit).
A9: Vital Core Research | B9: =COUNTIF(Transactions!B:B,A9) -> 4 | C9: =SUMIF(Transactions!B:B,A9,Transactions!D:D) -> 528.33 | D9: =SUMIF(Transactions!B:B,A9,Transactions!E:E) -> 97.89 | E9: =IFERROR(D9/B9,0) -> 24.4725 | F9: Full data. Activity resumed mid-May after account reinstated.
A10: Oasis Labs | B10: =COUNTIF(Transactions!B:B,A10) -> 5 | C10: =SUMIF(Transactions!B:B,A10,Transactions!D:D) -> 759.85 | D10: =SUMIF(Transactions!B:B,A10,Transactions!E:E) -> 68.66 | E10: =IFERROR(D10/B10,0) -> 13.732 | F10: Full data. Store credit payout model with $100 min threshold.
A11: Integrative Peptides | B11: =COUNTIF(Transactions!B:B,A11) -> 2 | C11: =SUMIF(Transactions!B:B,A11,Transactions!D:D) -> 0 | D11: =SUMIF(Transactions!B:B,A11,Transactions!E:E) -> 44.7 | E11: =IFERROR(D11/B11,0) -> 22.35 | F11: Commission paid as store credit on monthly cycle (15th to 14th).
A12: OVERALL TOTALS | B12: =SUM(B5:B11) -> 42 | C12: =SUM(C5:C11) -> 4598.26 | D12: =SUM(D5:D11) -> 1095.92 | E12: =IFERROR(D12/B12,0) -> 26.093333
A14: Data Source Note:
A15: Data compiled from Gmail commission notification emails. Some vendors (Peptide Partners, Ascension) send commission amounts only without sale totals. Affiliate dashboards on vendor sites may show additional historical commissions not yet reflected in email notifications — Peptide Partners in particular has substantial additional commission history visible in the dashboard. Royal Peptides "Refunded/Unpaid" entries represent referral orders where the commission was initially credited but later reverted to $0 by the vendor.

Sheet Transactions
A1: All Referral Transactions (Detail)
A2: Compiled from Gmail commission notification emails | Sorted by date (newest first)
A4: Date | B4: Vendor | C4: Order # | D4: Sale Amount | E4: Commission | F4: Status | G4: Notes
A5: 46160 | B5: Vital Core Research | C5: 32791 | D5: 84.93 | E5: 14.4 | F5: Active
A6: 46160 | B6: Vital Core Research | C6: 32790 | D6: 92.92 | E6: 15.99 | F6: Active
A7: 46160 | B7: Vital Core Research | C7: 32789 | D7: 44.92 | E7: 6.39 | F7: Active
A8: 46160 | B8: Royal Peptides | C8: 41503 | D8: 731.5 | E8: 70.65 | F8: Active
A9: 46159 | B9: Peptide Partners | E9: 68.4 | F9: Active
A10: 46159 | B10: Ascension Peptides | E10: 46.5 | F10: Active
A11: 46159 | B11: Ascension Peptides | E11: 18.37 | F11: Active
A12: 46159 | B12: Ascension Peptides | E12: 11.9 | F12: Active
A13: 46158 | B13: Peptide Partners | E13: 110.07 | F13: Active
A14: 46158 | B14: Peptide Partners | E14: 40.5 | F14: Active
A15: 46158 | B15: Peptide Partners | E15: 21.96 | F15: Active
A16: 46158 | B16: EZ Peptides | C16: 100877 | D16: 102.7 | E16: 9.27 | F16: Active
A17: 46158 | B17: EZ Peptides | C17: 100801 | D17: 216.9 | E17: 21.69 | F17: Active
A18: 46158 | B18: Ascension Peptides | E18: 76.55 | F18: Active
A19: 46158 | B19: Ascension Peptides | E19: 10.8 | F19: Active
A20: 46157 | B20: Peptide Partners | E20: 24.57 | F20: Active
A21: 46156 | B21: Vital Core Research | C21: 32748 | D21: 305.56 | E21: 61.11 | F21: Active
A22: 46156 | B22: Peptide Partners | E22: 54.9 | F22: Active
A23: 46156 | B23: Peptide Partners | E23: 24.57 | F23: Active
A24: 46156 | B24: Ascension Peptides | E24: 14.55 | F24: Active
A25: 46155 | B25: Peptide Partners | E25: 25.2 | F25: Active
A26: 46155 | B26: EZ Peptides | C26: 99862 | D26: 700 | E26: 66 | F26: Active
A27: 46155 | B27: EZ Peptides | C27: 99788 | D27: 89.2 | E27: 7.92 | F27: Active
A28: 46154 | B28: Peptide Partners | E28: 28.8 | F28: Active
A29: 46154 | B29: Peptide Partners | E29: 24.57 | F29: Active
A30: 46153 | B30: Royal Peptides | C30: 40787 | D30: 77.18 | E30: 0 | F30: Refunded/Unpaid | G30: Initial $5.85 → updated to $0
A31: 46153 | B31: Peptide Partners | E31: 0 | F31: Zero/refunded
A32: 46152 | B32: Peptide Partners | E32: 2.52 | F32: Active
A33: 46152 | B33: EZ Peptides | C33: 98307 | D33: 654 | E33: 65.4 | F33: Active
A34: 46150 | B34: Ascension Peptides | E34: 27.31 | F34: Active
A35: 46132 | B35: Oasis Labs | D35: 50.7 | E35: 3.38 | F35: Active
A36: 46111 | B36: Oasis Labs | D36: 18.8 | E36: 0.19 | F36: Active
A37: 46108 | B37: Oasis Labs | D37: 234.96 | E37: 22.7 | F37: Active
A38: 46102 | B38: Royal Peptides | C38: 33188 | D38: 132 | E38: 11.7 | F38: Active
A39: 46102 | B39: Royal Peptides | C39: 33187 | D39: 132 | E39: 0 | F39: Refunded/Unpaid | G39: Initial $11.70 → updated to $0
A40: 46102 | B40: Royal Peptides | C40: 33186 | D40: 138.6 | E40: 0 | F40: Refunded/Unpaid | G40: Initial $11.70 → updated to $0
A41: 46102 | B41: Royal Peptides | C41: 33185 | D41: 132 | E41: 0 | F41: Refunded/Unpaid | G41: Initial $11.70 → updated to $0
...
